<?xml version="1.0" encoding="UTF-8"?>
<testsuite name="labTest.WrongSumVerifyTest" tests="5" skipped="0" failures="5" errors="0" timestamp="2021-09-14T08:39:22" hostname="DESKTOP-I0JKDSF" time="99.627">
  <properties/>
  <testcase name="givenFilter_whenTheMostExpensiveProductAddedToCart_thenTotalPriceLessThanBound[0](model.RozetkaFilter@42cae5f1)" classname="labTest.WrongSumVerifyTest" time="42.555">
    <failure message="java.lang.AssertionError: expected [true] but found [false]" type="java.lang.AssertionError">java.lang.AssertionError: expected [true] but found [false]
	at org.testng.Assert.fail(Assert.java:96)
	at org.testng.Assert.failNotEquals(Assert.java:776)
	at org.testng.Assert.assertTrue(Assert.java:44)
	at org.testng.Assert.assertTrue(Assert.java:54)
	at labTest.WrongSumVerifyTest.givenFilter_whenTheMostExpensiveProductAddedToCart_thenTotalPriceLessThanBound(WrongSumVerifyTest.java:58)
	at java.base/jdk.internal.reflect.NativeMethodAccessorImpl.invoke0(Native Method)
	at java.base/jdk.internal.reflect.NativeMethodAccessorImpl.invoke(NativeMethodAccessorImpl.java:62)
	at java.base/jdk.internal.reflect.DelegatingMethodAccessorImpl.invoke(DelegatingMethodAccessorImpl.java:43)
	at java.base/java.lang.reflect.Method.invoke(Method.java:566)
	at org.testng.internal.MethodInvocationHelper.invokeMethod(MethodInvocationHelper.java:124)
	at org.testng.internal.Invoker.invokeMethod(Invoker.java:583)
	at org.testng.internal.Invoker.invokeTestMethod(Invoker.java:719)
	at org.testng.internal.TestMethodWithDataProviderMethodWorker.call(TestMethodWithDataProviderMethodWorker.java:71)
	at org.testng.internal.TestMethodWithDataProviderMethodWorker.call(TestMethodWithDataProviderMethodWorker.java:14)
	at java.base/java.util.concurrent.FutureTask.run(FutureTask.java:264)
	at java.base/java.util.concurrent.Executors$RunnableAdapter.call(Executors.java:515)
	at java.base/java.util.concurrent.FutureTask.run(FutureTask.java:264)
	at java.base/java.util.concurrent.ThreadPoolExecutor.runWorker(ThreadPoolExecutor.java:1128)
	at java.base/java.util.concurrent.ThreadPoolExecutor$Worker.run(ThreadPoolExecutor.java:628)
	at java.base/java.lang.Thread.run(Thread.java:834)
</failure>
  </testcase>
  <testcase name="givenFilter_whenTheMostExpensiveProductAddedToCart_thenTotalPriceLessThanBound[0](model.RozetkaFilter@6a86c132)" classname="labTest.WrongSumVerifyTest" time="56.208">
    <failure message="java.lang.AssertionError: expected [true] but found [false]" type="java.lang.AssertionError">java.lang.AssertionError: expected [true] but found [false]
	at org.testng.Assert.fail(Assert.java:96)
	at org.testng.Assert.failNotEquals(Assert.java:776)
	at org.testng.Assert.assertTrue(Assert.java:44)
	at org.testng.Assert.assertTrue(Assert.java:54)
	at labTest.WrongSumVerifyTest.givenFilter_whenTheMostExpensiveProductAddedToCart_thenTotalPriceLessThanBound(WrongSumVerifyTest.java:58)
	at java.base/jdk.internal.reflect.NativeMethodAccessorImpl.invoke0(Native Method)
	at java.base/jdk.internal.reflect.NativeMethodAccessorImpl.invoke(NativeMethodAccessorImpl.java:62)
	at java.base/jdk.internal.reflect.DelegatingMethodAccessorImpl.invoke(DelegatingMethodAccessorImpl.java:43)
	at java.base/java.lang.reflect.Method.invoke(Method.java:566)
	at org.testng.internal.MethodInvocationHelper.invokeMethod(MethodInvocationHelper.java:124)
	at org.testng.internal.Invoker.invokeMethod(Invoker.java:583)
	at org.testng.internal.Invoker.invokeTestMethod(Invoker.java:719)
	at org.testng.internal.TestMethodWithDataProviderMethodWorker.call(TestMethodWithDataProviderMethodWorker.java:71)
	at org.testng.internal.TestMethodWithDataProviderMethodWorker.call(TestMethodWithDataProviderMethodWorker.java:14)
	at java.base/java.util.concurrent.FutureTask.run(FutureTask.java:264)
	at java.base/java.util.concurrent.Executors$RunnableAdapter.call(Executors.java:515)
	at java.base/java.util.concurrent.FutureTask.run(FutureTask.java:264)
	at java.base/java.util.concurrent.ThreadPoolExecutor.runWorker(ThreadPoolExecutor.java:1128)
	at java.base/java.util.concurrent.ThreadPoolExecutor$Worker.run(ThreadPoolExecutor.java:628)
	at java.base/java.lang.Thread.run(Thread.java:834)
</failure>
  </testcase>
  <testcase name="givenFilter_whenTheMostExpensiveProductAddedToCart_thenTotalPriceLessThanBound[0](model.RozetkaFilter@51f3816d)" classname="labTest.WrongSumVerifyTest" time="57.196">
    <failure message="java.lang.AssertionError: expected [true] but found [false]" type="java.lang.AssertionError">java.lang.AssertionError: expected [true] but found [false]
	at org.testng.Assert.fail(Assert.java:96)
	at org.testng.Assert.failNotEquals(Assert.java:776)
	at org.testng.Assert.assertTrue(Assert.java:44)
	at org.testng.Assert.assertTrue(Assert.java:54)
	at labTest.WrongSumVerifyTest.givenFilter_whenTheMostExpensiveProductAddedToCart_thenTotalPriceLessThanBound(WrongSumVerifyTest.java:58)
	at java.base/jdk.internal.reflect.NativeMethodAccessorImpl.invoke0(Native Method)
	at java.base/jdk.internal.reflect.NativeMethodAccessorImpl.invoke(NativeMethodAccessorImpl.java:62)
	at java.base/jdk.internal.reflect.DelegatingMethodAccessorImpl.invoke(DelegatingMethodAccessorImpl.java:43)
	at java.base/java.lang.reflect.Method.invoke(Method.java:566)
	at org.testng.internal.MethodInvocationHelper.invokeMethod(MethodInvocationHelper.java:124)
	at org.testng.internal.Invoker.invokeMethod(Invoker.java:583)
	at org.testng.internal.Invoker.invokeTestMethod(Invoker.java:719)
	at org.testng.internal.TestMethodWithDataProviderMethodWorker.call(TestMethodWithDataProviderMethodWorker.java:71)
	at org.testng.internal.TestMethodWithDataProviderMethodWorker.call(TestMethodWithDataProviderMethodWorker.java:14)
	at java.base/java.util.concurrent.FutureTask.run(FutureTask.java:264)
	at java.base/java.util.concurrent.Executors$RunnableAdapter.call(Executors.java:515)
	at java.base/java.util.concurrent.FutureTask.run(FutureTask.java:264)
	at java.base/java.util.concurrent.ThreadPoolExecutor.runWorker(ThreadPoolExecutor.java:1128)
	at java.base/java.util.concurrent.ThreadPoolExecutor$Worker.run(ThreadPoolExecutor.java:628)
	at java.base/java.lang.Thread.run(Thread.java:834)
</failure>
  </testcase>
  <testcase name="givenFilter_whenTheMostExpensiveProductAddedToCart_thenTotalPriceLessThanBound[0](model.RozetkaFilter@19987d21)" classname="labTest.WrongSumVerifyTest" time="57.077">
    <failure message="java.lang.AssertionError: expected [true] but found [false]" type="java.lang.AssertionError">java.lang.AssertionError: expected [true] but found [false]
	at org.testng.Assert.fail(Assert.java:96)
	at org.testng.Assert.failNotEquals(Assert.java:776)
	at org.testng.Assert.assertTrue(Assert.java:44)
	at org.testng.Assert.assertTrue(Assert.java:54)
	at labTest.WrongSumVerifyTest.givenFilter_whenTheMostExpensiveProductAddedToCart_thenTotalPriceLessThanBound(WrongSumVerifyTest.java:58)
	at java.base/jdk.internal.reflect.NativeMethodAccessorImpl.invoke0(Native Method)
	at java.base/jdk.internal.reflect.NativeMethodAccessorImpl.invoke(NativeMethodAccessorImpl.java:62)
	at java.base/jdk.internal.reflect.DelegatingMethodAccessorImpl.invoke(DelegatingMethodAccessorImpl.java:43)
	at java.base/java.lang.reflect.Method.invoke(Method.java:566)
	at org.testng.internal.MethodInvocationHelper.invokeMethod(MethodInvocationHelper.java:124)
	at org.testng.internal.Invoker.invokeMethod(Invoker.java:583)
	at org.testng.internal.Invoker.invokeTestMethod(Invoker.java:719)
	at org.testng.internal.TestMethodWithDataProviderMethodWorker.call(TestMethodWithDataProviderMethodWorker.java:71)
	at org.testng.internal.TestMethodWithDataProviderMethodWorker.call(TestMethodWithDataProviderMethodWorker.java:14)
	at java.base/java.util.concurrent.FutureTask.run(FutureTask.java:264)
	at java.base/java.util.concurrent.Executors$RunnableAdapter.call(Executors.java:515)
	at java.base/java.util.concurrent.FutureTask.run(FutureTask.java:264)
	at java.base/java.util.concurrent.ThreadPoolExecutor.runWorker(ThreadPoolExecutor.java:1128)
	at java.base/java.util.concurrent.ThreadPoolExecutor$Worker.run(ThreadPoolExecutor.java:628)
	at java.base/java.lang.Thread.run(Thread.java:834)
</failure>
  </testcase>
  <testcase name="givenFilter_whenTheMostExpensiveProductAddedToCart_thenTotalPriceLessThanBound[1](model.RozetkaFilter@390a8a65)" classname="labTest.WrongSumVerifyTest" time="53.815">
    <failure message="java.lang.AssertionError: expected [true] but found [false]" type="java.lang.AssertionError">java.lang.AssertionError: expected [true] but found [false]
	at org.testng.Assert.fail(Assert.java:96)
	at org.testng.Assert.failNotEquals(Assert.java:776)
	at org.testng.Assert.assertTrue(Assert.java:44)
	at org.testng.Assert.assertTrue(Assert.java:54)
	at labTest.WrongSumVerifyTest.givenFilter_whenTheMostExpensiveProductAddedToCart_thenTotalPriceLessThanBound(WrongSumVerifyTest.java:58)
	at java.base/jdk.internal.reflect.NativeMethodAccessorImpl.invoke0(Native Method)
	at java.base/jdk.internal.reflect.NativeMethodAccessorImpl.invoke(NativeMethodAccessorImpl.java:62)
	at java.base/jdk.internal.reflect.DelegatingMethodAccessorImpl.invoke(DelegatingMethodAccessorImpl.java:43)
	at java.base/java.lang.reflect.Method.invoke(Method.java:566)
	at org.testng.internal.MethodInvocationHelper.invokeMethod(MethodInvocationHelper.java:124)
	at org.testng.internal.Invoker.invokeMethod(Invoker.java:583)
	at org.testng.internal.Invoker.invokeTestMethod(Invoker.java:719)
	at org.testng.internal.TestMethodWithDataProviderMethodWorker.call(TestMethodWithDataProviderMethodWorker.java:71)
	at org.testng.internal.TestMethodWithDataProviderMethodWorker.call(TestMethodWithDataProviderMethodWorker.java:14)
	at java.base/java.util.concurrent.FutureTask.run(FutureTask.java:264)
	at java.base/java.util.concurrent.Executors$RunnableAdapter.call(Executors.java:515)
	at java.base/java.util.concurrent.FutureTask.run(FutureTask.java:264)
	at java.base/java.util.concurrent.ThreadPoolExecutor.runWorker(ThreadPoolExecutor.java:1128)
	at java.base/java.util.concurrent.ThreadPoolExecutor$Worker.run(ThreadPoolExecutor.java:628)
	at java.base/java.lang.Thread.run(Thread.java:834)
</failure>
  </testcase>
  <system-out><![CDATA[[11:39:22 INFO] givenFilter_whenTheMostExpensiveProductAddedToCart_thenTotalPriceLessThanBound Started
[11:39:22 INFO] 
[11:39:22 INFO] givenFilter_whenTheMostExpensiveProductAddedToCart_thenTotalPriceLessThanBound Started
[11:39:22 INFO] 
[11:39:22 INFO] givenFilter_whenTheMostExpensiveProductAddedToCart_thenTotalPriceLessThanBound Started
[11:39:22 INFO] 
[11:39:22 INFO] givenFilter_whenTheMostExpensiveProductAddedToCart_thenTotalPriceLessThanBound Started
[11:39:22 INFO] 
[11:40:04 INFO] Failed because of - java.lang.AssertionError: expected [true] but found [false]
[11:40:08 INFO] givenFilter_whenTheMostExpensiveProductAddedToCart_thenTotalPriceLessThanBound Started
[11:40:08 INFO] 
[11:40:18 INFO] Failed because of - java.lang.AssertionError: expected [true] but found [false]
[11:40:19 INFO] Failed because of - java.lang.AssertionError: expected [true] but found [false]
[11:40:19 INFO] Failed because of - java.lang.AssertionError: expected [true] but found [false]
[11:41:01 INFO] Failed because of - java.lang.AssertionError: expected [true] but found [false]
]]></system-out>
  <system-err><![CDATA[Starting ChromeDriver 92.0.4515.43 (8c61b7e2989f2990d42f859cac71319137787cce-refs/branch-heads/4515@{#306}) on port 12783
Only local connections are allowed.
Please see https://chromedriver.chromium.org/security-considerations for suggestions on keeping ChromeDriver safe.
Starting ChromeDriver 92.0.4515.43 (8c61b7e2989f2990d42f859cac71319137787cce-refs/branch-heads/4515@{#306}) on port 19246
Only local connections are allowed.
Please see https://chromedriver.chromium.org/security-considerations for suggestions on keeping ChromeDriver safe.
ChromeDriver was started successfully.
Starting ChromeDriver 92.0.4515.43 (8c61b7e2989f2990d42f859cac71319137787cce-refs/branch-heads/4515@{#306}) on port 38444
Only local connections are allowed.
Please see https://chromedriver.chromium.org/security-considerations for suggestions on keeping ChromeDriver safe.
ChromeDriver was started successfully.
Starting ChromeDriver 92.0.4515.43 (8c61b7e2989f2990d42f859cac71319137787cce-refs/branch-heads/4515@{#306}) on port 19278
Only local connections are allowed.
Please see https://chromedriver.chromium.org/security-considerations for suggestions on keeping ChromeDriver safe.
ChromeDriver was started successfully.
ChromeDriver was started successfully.
[1631608759.935][WARNING]: This version of ChromeDriver has not been tested with Chrome version 93.
сент. 14, 2021 11:39:19 AM org.openqa.selenium.remote.ProtocolHandshake createSession
INFO: Detected dialect: W3C
[1631608760.002][WARNING]: This version of ChromeDriver has not been tested with Chrome version 93.
[1631608760.014][WARNING]: This version of ChromeDriver has not been tested with Chrome version 93.
сент. 14, 2021 11:39:20 AM org.openqa.selenium.remote.ProtocolHandshake createSession
INFO: Detected dialect: W3C
сент. 14, 2021 11:39:20 AM org.openqa.selenium.remote.ProtocolHandshake createSession
INFO: Detected dialect: W3C
[1631608760.044][WARNING]: This version of ChromeDriver has not been tested with Chrome version 93.
сент. 14, 2021 11:39:20 AM org.openqa.selenium.remote.ProtocolHandshake createSession
INFO: Detected dialect: W3C
Starting ChromeDriver 92.0.4515.43 (8c61b7e2989f2990d42f859cac71319137787cce-refs/branch-heads/4515@{#306}) on port 25529
Only local connections are allowed.
Please see https://chromedriver.chromium.org/security-considerations for suggestions on keeping ChromeDriver safe.
ChromeDriver was started successfully.
[1631608806.590][WARNING]: This version of ChromeDriver has not been tested with Chrome version 93.
сент. 14, 2021 11:40:06 AM org.openqa.selenium.remote.ProtocolHandshake createSession
INFO: Detected dialect: W3C
]]></system-err>
</testsuite>
