<?xml version="1.0" encoding="UTF-8"?>
<testsuite name="labTest.WrongSumVerifyTest" tests="4" skipped="0" failures="4" errors="0" timestamp="2021-09-14T09:35:38" hostname="DESKTOP-I0JKDSF" time="68.518">
  <properties/>
  <testcase name="givenFilter_whenTheMostExpensiveProductAddedToCart_thenTotalPriceLessThanBound[0](model.RozetkaFilter@37a62be)" classname="labTest.WrongSumVerifyTest" time="54.632">
    <failure message="java.lang.AssertionError: expected [true] but found [false]" type="java.lang.AssertionError">java.lang.AssertionError: expected [true] but found [false]
	at org.testng.Assert.fail(Assert.java:96)
	at org.testng.Assert.failNotEquals(Assert.java:776)
	at org.testng.Assert.assertTrue(Assert.java:44)
	at org.testng.Assert.assertTrue(Assert.java:54)
	at labTest.WrongSumVerifyTest.givenFilter_whenTheMostExpensiveProductAddedToCart_thenTotalPriceLessThanBound(WrongSumVerifyTest.java:58)
	at java.base/jdk.internal.reflect.NativeMethodAccessorImpl.invoke0(Native Method)
	at java.base/jdk.internal.reflect.NativeMethodAccessorImpl.invoke(NativeMethodAccessorImpl.java:62)
	at java.base/jdk.internal.reflect.DelegatingMethodAccessorImpl.invoke(DelegatingMethodAccessorImpl.java:43)
	at java.base/java.lang.reflect.Method.invoke(Method.java:566)
	at org.testng.internal.MethodInvocationHelper.invokeMethod(MethodInvocationHelper.java:124)
	at org.testng.internal.Invoker.invokeMethod(Invoker.java:583)
	at org.testng.internal.Invoker.invokeTestMethod(Invoker.java:719)
	at org.testng.internal.TestMethodWithDataProviderMethodWorker.call(TestMethodWithDataProviderMethodWorker.java:71)
	at org.testng.internal.TestMethodWithDataProviderMethodWorker.call(TestMethodWithDataProviderMethodWorker.java:14)
	at java.base/java.util.concurrent.FutureTask.run(FutureTask.java:264)
	at java.base/java.util.concurrent.Executors$RunnableAdapter.call(Executors.java:515)
	at java.base/java.util.concurrent.FutureTask.run(FutureTask.java:264)
	at java.base/java.util.concurrent.ThreadPoolExecutor.runWorker(ThreadPoolExecutor.java:1128)
	at java.base/java.util.concurrent.ThreadPoolExecutor$Worker.run(ThreadPoolExecutor.java:628)
	at java.base/java.lang.Thread.run(Thread.java:834)
</failure>
  </testcase>
  <testcase name="givenFilter_whenTheMostExpensiveProductAddedToCart_thenTotalPriceLessThanBound[0](model.RozetkaFilter@7d29a7f0)" classname="labTest.WrongSumVerifyTest" time="66.406">
    <failure message="java.lang.AssertionError: expected [true] but found [false]" type="java.lang.AssertionError">java.lang.AssertionError: expected [true] but found [false]
	at org.testng.Assert.fail(Assert.java:96)
	at org.testng.Assert.failNotEquals(Assert.java:776)
	at org.testng.Assert.assertTrue(Assert.java:44)
	at org.testng.Assert.assertTrue(Assert.java:54)
	at labTest.WrongSumVerifyTest.givenFilter_whenTheMostExpensiveProductAddedToCart_thenTotalPriceLessThanBound(WrongSumVerifyTest.java:58)
	at java.base/jdk.internal.reflect.NativeMethodAccessorImpl.invoke0(Native Method)
	at java.base/jdk.internal.reflect.NativeMethodAccessorImpl.invoke(NativeMethodAccessorImpl.java:62)
	at java.base/jdk.internal.reflect.DelegatingMethodAccessorImpl.invoke(DelegatingMethodAccessorImpl.java:43)
	at java.base/java.lang.reflect.Method.invoke(Method.java:566)
	at org.testng.internal.MethodInvocationHelper.invokeMethod(MethodInvocationHelper.java:124)
	at org.testng.internal.Invoker.invokeMethod(Invoker.java:583)
	at org.testng.internal.Invoker.invokeTestMethod(Invoker.java:719)
	at org.testng.internal.TestMethodWithDataProviderMethodWorker.call(TestMethodWithDataProviderMethodWorker.java:71)
	at org.testng.internal.TestMethodWithDataProviderMethodWorker.call(TestMethodWithDataProviderMethodWorker.java:14)
	at java.base/java.util.concurrent.FutureTask.run(FutureTask.java:264)
	at java.base/java.util.concurrent.Executors$RunnableAdapter.call(Executors.java:515)
	at java.base/java.util.concurrent.FutureTask.run(FutureTask.java:264)
	at java.base/java.util.concurrent.ThreadPoolExecutor.runWorker(ThreadPoolExecutor.java:1128)
	at java.base/java.util.concurrent.ThreadPoolExecutor$Worker.run(ThreadPoolExecutor.java:628)
	at java.base/java.lang.Thread.run(Thread.java:834)
</failure>
  </testcase>
  <testcase name="givenFilter_whenTheMostExpensiveProductAddedToCart_thenTotalPriceLessThanBound[0](model.RozetkaFilter@376138b3)" classname="labTest.WrongSumVerifyTest" time="66.671">
    <failure message="java.lang.AssertionError: expected [true] but found [false]" type="java.lang.AssertionError">java.lang.AssertionError: expected [true] but found [false]
	at org.testng.Assert.fail(Assert.java:96)
	at org.testng.Assert.failNotEquals(Assert.java:776)
	at org.testng.Assert.assertTrue(Assert.java:44)
	at org.testng.Assert.assertTrue(Assert.java:54)
	at labTest.WrongSumVerifyTest.givenFilter_whenTheMostExpensiveProductAddedToCart_thenTotalPriceLessThanBound(WrongSumVerifyTest.java:58)
	at java.base/jdk.internal.reflect.NativeMethodAccessorImpl.invoke0(Native Method)
	at java.base/jdk.internal.reflect.NativeMethodAccessorImpl.invoke(NativeMethodAccessorImpl.java:62)
	at java.base/jdk.internal.reflect.DelegatingMethodAccessorImpl.invoke(DelegatingMethodAccessorImpl.java:43)
	at java.base/java.lang.reflect.Method.invoke(Method.java:566)
	at org.testng.internal.MethodInvocationHelper.invokeMethod(MethodInvocationHelper.java:124)
	at org.testng.internal.Invoker.invokeMethod(Invoker.java:583)
	at org.testng.internal.Invoker.invokeTestMethod(Invoker.java:719)
	at org.testng.internal.TestMethodWithDataProviderMethodWorker.call(TestMethodWithDataProviderMethodWorker.java:71)
	at org.testng.internal.TestMethodWithDataProviderMethodWorker.call(TestMethodWithDataProviderMethodWorker.java:14)
	at java.base/java.util.concurrent.FutureTask.run(FutureTask.java:264)
	at java.base/java.util.concurrent.Executors$RunnableAdapter.call(Executors.java:515)
	at java.base/java.util.concurrent.FutureTask.run(FutureTask.java:264)
	at java.base/java.util.concurrent.ThreadPoolExecutor.runWorker(ThreadPoolExecutor.java:1128)
	at java.base/java.util.concurrent.ThreadPoolExecutor$Worker.run(ThreadPoolExecutor.java:628)
	at java.base/java.lang.Thread.run(Thread.java:834)
</failure>
  </testcase>
  <testcase name="givenFilter_whenTheMostExpensiveProductAddedToCart_thenTotalPriceLessThanBound[0](model.RozetkaFilter@49ef8982)" classname="labTest.WrongSumVerifyTest" time="68.59">
    <failure message="java.lang.AssertionError: expected [true] but found [false]" type="java.lang.AssertionError">java.lang.AssertionError: expected [true] but found [false]
	at org.testng.Assert.fail(Assert.java:96)
	at org.testng.Assert.failNotEquals(Assert.java:776)
	at org.testng.Assert.assertTrue(Assert.java:44)
	at org.testng.Assert.assertTrue(Assert.java:54)
	at labTest.WrongSumVerifyTest.givenFilter_whenTheMostExpensiveProductAddedToCart_thenTotalPriceLessThanBound(WrongSumVerifyTest.java:58)
	at java.base/jdk.internal.reflect.NativeMethodAccessorImpl.invoke0(Native Method)
	at java.base/jdk.internal.reflect.NativeMethodAccessorImpl.invoke(NativeMethodAccessorImpl.java:62)
	at java.base/jdk.internal.reflect.DelegatingMethodAccessorImpl.invoke(DelegatingMethodAccessorImpl.java:43)
	at java.base/java.lang.reflect.Method.invoke(Method.java:566)
	at org.testng.internal.MethodInvocationHelper.invokeMethod(MethodInvocationHelper.java:124)
	at org.testng.internal.Invoker.invokeMethod(Invoker.java:583)
	at org.testng.internal.Invoker.invokeTestMethod(Invoker.java:719)
	at org.testng.internal.TestMethodWithDataProviderMethodWorker.call(TestMethodWithDataProviderMethodWorker.java:71)
	at org.testng.internal.TestMethodWithDataProviderMethodWorker.call(TestMethodWithDataProviderMethodWorker.java:14)
	at java.base/java.util.concurrent.FutureTask.run(FutureTask.java:264)
	at java.base/java.util.concurrent.Executors$RunnableAdapter.call(Executors.java:515)
	at java.base/java.util.concurrent.FutureTask.run(FutureTask.java:264)
	at java.base/java.util.concurrent.ThreadPoolExecutor.runWorker(ThreadPoolExecutor.java:1128)
	at java.base/java.util.concurrent.ThreadPoolExecutor$Worker.run(ThreadPoolExecutor.java:628)
	at java.base/java.lang.Thread.run(Thread.java:834)
</failure>
  </testcase>
  <system-out><![CDATA[[12:35:38 INFO] givenFilter_whenTheMostExpensiveProductAddedToCart_thenTotalPriceLessThanBound Started
[12:35:38 INFO] 
[12:35:38 INFO] givenFilter_whenTheMostExpensiveProductAddedToCart_thenTotalPriceLessThanBound Started
[12:35:38 INFO] 
[12:35:38 INFO] givenFilter_whenTheMostExpensiveProductAddedToCart_thenTotalPriceLessThanBound Started
[12:35:38 INFO] 
[12:35:38 INFO] givenFilter_whenTheMostExpensiveProductAddedToCart_thenTotalPriceLessThanBound Started
[12:35:38 INFO] 
[12:36:33 INFO] Failed because of - java.lang.AssertionError: expected [true] but found [false]
[12:36:45 INFO] Failed because of - java.lang.AssertionError: expected [true] but found [false]
[12:36:45 INFO] Failed because of - java.lang.AssertionError: expected [true] but found [false]
[12:36:47 INFO] Failed because of - java.lang.AssertionError: expected [true] but found [false]
]]></system-out>
  <system-err><![CDATA[Starting ChromeDriver 92.0.4515.43 (8c61b7e2989f2990d42f859cac71319137787cce-refs/branch-heads/4515@{#306}) on port 27336
Only local connections are allowed.
Please see https://chromedriver.chromium.org/security-considerations for suggestions on keeping ChromeDriver safe.
Starting ChromeDriver 92.0.4515.43 (8c61b7e2989f2990d42f859cac71319137787cce-refs/branch-heads/4515@{#306}) on port 43058
Only local connections are allowed.
Please see https://chromedriver.chromium.org/security-considerations for suggestions on keeping ChromeDriver safe.
Starting ChromeDriver 92.0.4515.43 (8c61b7e2989f2990d42f859cac71319137787cce-refs/branch-heads/4515@{#306}) on port 45104
Only local connections are allowed.
Please see https://chromedriver.chromium.org/security-considerations for suggestions on keeping ChromeDriver safe.
ChromeDriver was started successfully.
ChromeDriver was started successfully.
ChromeDriver was started successfully.
Starting ChromeDriver 92.0.4515.43 (8c61b7e2989f2990d42f859cac71319137787cce-refs/branch-heads/4515@{#306}) on port 7844
Only local connections are allowed.
Please see https://chromedriver.chromium.org/security-considerations for suggestions on keeping ChromeDriver safe.
ChromeDriver was started successfully.
[1631612134.970][WARNING]: This version of ChromeDriver has not been tested with Chrome version 93.
[1631612135.041][WARNING]: This version of ChromeDriver has not been tested with Chrome version 93.
[1631612135.051][WARNING]: This version of ChromeDriver has not been tested with Chrome version 93.
[1631612135.114][WARNING]: This version of ChromeDriver has not been tested with Chrome version 93.
сент. 14, 2021 12:35:35 PM org.openqa.selenium.remote.ProtocolHandshake createSession
INFO: Detected dialect: W3C
сент. 14, 2021 12:35:35 PM org.openqa.selenium.remote.ProtocolHandshake createSession
INFO: Detected dialect: W3C
сент. 14, 2021 12:35:35 PM org.openqa.selenium.remote.ProtocolHandshake createSession
INFO: Detected dialect: W3C
сент. 14, 2021 12:35:35 PM org.openqa.selenium.remote.ProtocolHandshake createSession
INFO: Detected dialect: W3C
]]></system-err>
</testsuite>
